<?xml version="1.0"?>
<robot name="person" xmlns:xacro="http://www.ros.org/wiki/xacro">

        <pose frame=''>30 0 0 0 0 0</pose>
        <scale>1 1 1</scale>
        <link name='ped_link_2'>
        <gravity>0</gravity>
        <inertial>
          <pose frame=''>30 0 0 0 -0 0</pose>
          <mass>80</mass>
          <inertia>
            <ixx>27.82</ixx>
            <ixy>0</ixy>
            <ixz>0</ixz>
            <iyy>24.88</iyy>
            <iyz>0</iyz>
            <izz>4.57</izz>
          </inertia>
        </inertial>
          <collision name='bottom'>
            <pose frame=''>30 0 0.01 0 -0 0</pose>
               <geometry>
                 <box>
                   <size>0.35 0.75 0.02</size>
                 </box>
               </geometry>
               <max_contacts>10</max_contacts>
               <surface>
                 <contact>
                   <ode/>
                 </contact>
                 <bounce/>
                 <friction>
                   <torsional>
                     <ode/>
                   </torsional>
                   <ode/>
                 </friction>
               </surface>
             </collision>
             <collision name='person_2'>
               <pose frame=''>30 0 0.02 0 -0 0</pose>
               <geometry>
                 <mesh>
                   <uri>model://person_walking/meshes/walking.dae</uri>
                 </mesh>
               </geometry>
               <max_contacts>10</max_contacts>
               <surface>
                 <contact>
                   <ode/>
                 </contact>
                 <bounce/>
                 <friction>
                   <torsional>
                     <ode/>
                   </torsional>
                   <ode/>
                 </friction>
               </surface>
             </collision>
             <visual name='visual'>
               <pose frame=''>30 0 0 0 -0 0</pose>
               <geometry>
                 <mesh>
                   <uri>model://person_walking/meshes/walking.dae</uri>
                 </mesh>
               </geometry>
             </visual>
             <self_collide>0</self_collide>
             <enable_wind>0</enable_wind>
             <kinematic>0</kinematic>
          </link>
          <pose frame=''>30 0 0 0 -0 0</pose>
          <joint name="ped_joint_2" type="planar">
            <origin xyz="0 0 0" rpy="0 0 0" />
            <parent link="map"/>
            <child link="ped_link_2" />
          </joint>
          <transmission name="ped_trans_2">
            <type>transmission_interface/SimpleTransmission</type>
            <joint name="ped_joint">
              <hardwareInterface>PositionJointInterface</hardwareInterface>
            </joint>
            <actuator name="ped_actuator_2">
              <mechanicalReduction>1</mechanicalReduction>
            </actuator>
          </transmission>
          <plugin name="object_controller_2" filename="libgazebo_ros_planar_move.so">
            <commandTopic>ped_vel</commandTopic>
            <odometryTopic>odom</odometryTopic>
            <odometryFrame>odom</odometryFrame>
            <odometryRate>10.0</odometryRate>
            <robotBaseFrame>ped_link_2</robotBaseFrame>
          </plugin>

</robot>